File: data/ppms/surf/para/200K.dat
[Header]
;Copyright 2015, Quantum Design, Inc. All rights reserved.
FILEOPENTIME, 0.0, ,7/29/2023 11:33:33 PM
BYAPP, Electrical Transport Option, Release 1.1.3 Build 5
INFO, APPNAME, ETOption, Release 1.1.3 Build 5
TITLE, Electrical Transport Option (CAN)
STARTUPAXIS, X, 2, LINEAR, AUTO
STARTUPAXIS, Y1, 7, LINEAR, AUTO
STARTUPAXIS, Y2, 9, LINEAR, AUTO
STARTUPAXIS, Y3, 27, LINEAR, AUTO
STARTUPAXIS, Y4, 29, LINEAR, AUTO
TIMEMODE, SECONDS, RELATIVE
PLOT_APPEARANCE, ALL, HORZ_GRID_ON, VERT_GRID_ON,,AUTO_LINES
RECORDS, ALL_RECORDS
DATATYPE, COMMENT, 1
[Data]
Comment,Time Stamp (s),Temperature (K),Field (Oe),Sample Position (deg),Chamber Pressure (Torr),Resistance Ch1 (Ohms),Resistance Std. Dev. Ch1 (Ohms),Phase Angle Ch1 (deg),I-V Current Ch1 (mA),I-V Voltage Ch1 (V),Frequency Ch1 (Hz),Averaging Time Ch1 (s),AC Current Ch1 (mA),DC Current Ch1 (mA),Voltage Ampl Ch1 (V),In Phase Voltage Ampl Ch1 (V),Quadrature Voltage Ch1 (V),AC Voltage Ch1 (V),DC Voltage Ch1 (V),Current Ampl Ch1 (mA),In Phase Current Ch1 (mA),Quadrature Current Ch1 (mA),Gain Ch1,2nd Harmonic Ch1 (dB),3rd Harmonic Ch1 (dB),Resistance Ch2 (Ohms),Resistance Std. Dev. Ch2 (Ohms),Phase Angle Ch2 (deg),I-V Current Ch2 (mA),I-V Voltage Ch2 (V),Frequency Ch2 (Hz),Averaging Time Ch2 (s),AC Current Ch2 (mA),DC Current Ch2 (mA),Voltage Ampl Ch2 (V),In Phase Voltage Ampl Ch2 (V),Quadrature Voltage Ch2 (V),AC Voltage Ch2 (V),DC Voltage Ch2 (V),Current Ampl Ch2 (mA),In Phase Current Ch2 (mA),Quadrature Current Ch2 (mA),Gain Ch2,2nd Harmonic Ch2 (dB),3rd Harmonic Ch2 (dB),ETO Status Code,ETO Measurement Mode,Temperature Status (code),Field Status (code),Chamber Status (code),ETO Channel 1,ETO Channel 2,ETO Channel 3,ETO Channel 4,ETO Channel 5,ETO Channel 6,ETO Channel 7,ETO Channel 8,ETO Channel 9,ETO Channel 10,ETO Channel 11,ETO Channel 12,ETO Channel 13,ETO Channel 14,ETO Channel 15,ETO Channel 16

Ch. 1 Input voltage exceeded compliance limit.,3899835212.50501,200.008407592773,88469.5078125,90,14.952,188.7878,0,-0.0288305,,,0.4359754,2.293708,0.1,0,0.01887722,0.01887722,-9.498774E-06,,,,,,100,-70.64951,-64.50652,,,,,,,,,,,,,,,,,,,,,48536448,0,1,6,1,,,,,,,,,,,,,,,,
Ch. 1 Input voltage exceeded compliance limit.,3899835233.91102,200.005706787109,87416.9921875,90,14.966,188.8988,0,0.006065478,,,0.4359754,2.293708,0.1,0,0.01888831,0.01888831,1.999565E-06,,,,,,100,-69.17796,-62.09752,,,,,,,,,,,,,,,,,,,,,48536448,0,1,6,1,,,,,,,,,,,,,,,,
Ch. 1 Input voltage exceeded compliance limit.,3899835253.83056,200.007080078125,86429.0859375,90,15.002,189.1949,0,-0.01474781,,,0.4359754,2.293708,0.1,0,0.01891792,0.01891792,-4.869432E-06,,,,,,100,-70.60067,-71.90314,,,,,,,,,,,,,,,,,,,,,48536448,0,1,6,1,,,,,,,,,,,,,,,,
Ch. 1 Input voltage exceeded compliance limit.,3899835274.92288,200.00537109375,85391.71875,90,15.012,189.25,0,-0.003836381,,,0.4359754,2.293708,0.1,0,0.01892343,0.01892343,-1.267065E-06,,,,,,100,-71.61234,-60.23727,,,,,,,,,,,,,,,,,,,,,48536448,0,1,6,1,,,,,,,,,,,,,,,,
Ch. 1 Input voltage exceeded compliance limit.,3899835294.55501,200.004699707031,84418.5859375,90,15.015,189.6416,0,-0.01258187,,,0.4359754,2.293708,0.1,0,0.01896258,0.01896258,-4.16409E-06,,,,,,100,-64.44861,-69.19547,,,,,,,,,,,,,,,,,,,,,48536448,0,1,6,1,,,,,,,,,,,,,,,,
Ch. 1 Input voltage exceeded compliance limit.,3899835315.4727,200.00602722168,83381.2109375,90,15.022,189.6761,0,-0.004077463,,,0.4359754,2.293708,0.1,0,0.01896603,0.01896603,-1.349721E-06,,,,,,100,-59.92284,-69.96414,,,,,,,,,,,,,,,,,,,,,48536448,0,1,6,1,,,,,,,,,,,,,,,,
Ch. 1 Input voltage exceeded compliance limit.,3899835335.47902,200.004776000977,82398.1953125,90,15.039,189.9987,0,-0.01562657,,,0.4359754,2.293708,0.1,0,0.01899829,0.01899829,-5.1815E-06,,,,,,100,-67.31902,-75.41577,,,,,,,,,,,,,,,,,,,,,48536448,0,1,6,1,,,,,,,,,,,,,,,,
Ch. 1 Input voltage exceeded compliance limit.,3899835356.73666,200.00537109375,81346.2734375,90,15.09,189.8936,0,-0.01913777,,,0.4359754,2.293708,0.1,0,0.01898779,0.01898778,-6.342244E-06,,,,,,100,-66.71775,-72.84858,,,,,,,,,,,,,,,,,,,,,48536448,0,1,6,1,,,,,,,,,,,,,,,,
Ch. 1 Input voltage exceeded compliance limit.,3899835376.49505,200.005172729492,80367.8828125,90,15.103,189.9234,0,-0.01927904,,,0.4359754,2.293708,0.1,0,0.01899077,0.01899076,-6.390065E-06,,,,,,100,-64.56295,-74.12817,,,,,,,,,,,,,,,,,,,,,48536448,0,1,6,1,,,,,,,,,,,,,,,,
Ch. 1 Input voltage exceeded compliance limit.,3899835396.45925,200.004302978516,79384.90625,90,15.102,190.0193,0,-0.01866365,,,0.4359754,2.293708,0.1,0,0.01900036,0.01900036,-6.189219E-06,,,,,,100,-68.47202,-90.71181,,,,,,,,,,,,,,,,,,,,,48536448,0,1,6,1,,,,,,,,,,,,,,,,
Ch. 1 Input voltage exceeded compliance limit.,3899835417.34975,200.004379272461,78352.546875,90,15.116,190.0504,0,-0.02417833,,,0.4359754,2.293708,0.1,0,0.01900346,0.01900346,-8.019299E-06,,,,,,100,-59.59609,-76.02882,,,,,,,,,,,,,,,,,,,,,48536448,0,1,6,1,,,,,,,,,,,,,,,,
Ch. 1 Input voltage exceeded compliance limit.,3899835437.32609,200.004104614258,77363.9765625,90,15.121,190.1748,0,-0.02001155,,,0.4359754,2.293708,0.1,0,0.0190159,0.0190159,-6.641634E-06,,,,,,100,-62.87793,-62.92374,,,,,,,,,,,,,,,,,,,,,48536448,0,1,6,1,,,,,,,,,,,,,,,,
Ch. 1 Input voltage exceeded compliance limit.,3899835458.44151,200.002990722656,76321.8125,90,15.156,190.4541,0,-0.02473762,,,0.4359754,2.293708,0.1,0,0.01904383,0.01904383,-8.222229E-06,,,,,,100,-67.88854,-75.38201,,,,,,,,,,,,,,,,,,,,,48536448,0,1,6,1,,,,,,,,,,,,,,,,
Ch. 1 Input voltage exceeded compliance limit.,3899835477.96754,200.003646850586,75353.40625,90,15.173,190.6313,0,-0.03172199,,,0.4359754,2.293708,0.1,0,0.01906155,0.01906155,-1.055349E-05,,,,,,100,-69.60683,-78.23167,,,,,,,,,,,,,,,,,,,,,48536448,0,1,6,1,,,,,,,,,,,,,,,,
Ch. 1 Input voltage exceeded compliance limit.,3899835499.47119,200.001068115234,74295.703125,90,15.13,190.4061,0,-0.02739217,,,0.4359754,2.293708,0.1,0,0.01903903,0.01903903,-9.102246E-06,,,,,,100,-60.35645,-64.08844,,,,,,,,,,,,,,,,,,,,,48536448,0,1,6,1,,,,,,,,,,,,,,,,
Ch. 1 Input voltage exceeded compliance limit.,3899835519.34061,200.002456665039,73312.546875,90,15.14,190.4714,0,-0.04733106,,,0.4359754,2.293708,0.1,0,0.01904556,0.01904556,-1.573321E-05,,,,,,100,-63.89116,-59.59587,,,,,,,,,,,,,,,,,,,,,48536448,0,1,6,1,,,,,,,,,,,,,,,,
Ch. 1 Input voltage exceeded compliance limit.,3899835540.66931,200.003112792969,72260.1171875,90,15.137,190.8827,0,-0.02825268,,,0.4359754,2.293708,0.1,0,0.01908669,0.01908669,-9.411691E-06,,,,,,100,-72.6329,-75.75574,,,,,,,,,,,,,,,,,,,,,48536448,0,1,6,1,,,,,,,,,,,,,,,,
Ch. 1 Input voltage exceeded compliance limit.,3899835560.34345,200.002395629883,71286.859375,90,15.129,190.9207,0,-0.03243944,,,0.4359754,2.293708,0.1,0,0.01909049,0.01909049,-1.080856E-05,,,,,,100,-69.47791,-60.81248,,,,,,,,,,,,,,,,,,,,,48536448,0,1,6,1,,,,,,,,,,,,,,,,
Ch. 1 Input voltage exceeded compliance limit.,3899835581.186,200.002456665039,70254.6875,90,15.131,191.2422,0,-0.02206543,,,0.4359754,2.293708,0.1,0,0.01912264,0.01912264,-7.364406E-06,,,,,,100,-65.69247,-74.87157,,,,,,,,,,,,,,,,,,,,,48536448,0,1,6,1,,,,,,,,,,,,,,,,
Ch. 1 Input voltage exceeded compliance limit.,3899835601.00088,200.001724243164,69276.65625,90,15.141,191.25,0,-0.01355143,,,0.4359754,2.293708,0.1,0,0.01912341,0.01912341,-4.523012E-06,,,,,,100,-80.00202,-70.12057,,,,,,,,,,,,,,,,,,,,,48536448,0,1,6,1,,,,,,,,,,,,,,,,
Ch. 1 Input voltage exceeded compliance limit.,3899835625.85651,200.002456665039,68051.6484375,90,15.146,191.3659,0,-0.02419125,,,0.4359754,2.293708,0.1,0,0.01913501,0.01913501,-8.079125E-06,,,,,,100,-68.94243,-66.03843,,,,,,,,,,,,,,,,,,,,,48536448,0,1,6,1,,,,,,,,,,,,,,,,
Ch. 1 Input voltage exceeded compliance limit.,3899835647.52049,199.999221801758,66979.546875,90,15.144,191.6438,0,-0.02941499,,,0.4359754,2.293708,0.1,0,0.01916279,0.01916279,-9.837954E-06,,,,,,100,-67.49773,-69.66357,,,,,,,,,,,,,,,,,,,,,48536448,0,1,6,1,,,,,,,,,,,,,,,,
Ch. 1 Input voltage exceeded compliance limit.,3899835667.30794,200.001266479492,65996.5546875,90,15.12,191.3999,0,-0.02129478,,,0.4359754,2.293708,0.1,0,0.01913841,0.0191384,-7.113057E-06,,,,,,100,-69.29885,-71.28117,,,,,,,,,,,,,,,,,,,,,48536448,0,1,6,1,,,,,,,,,,,,,,,,
Ch. 1 Input voltage exceeded compliance limit.,3899835687.9793,200.001068115234,64979.01953125,90,15.134,191.9298,0,-0.01072813,,,0.4359754,2.293708,0.1,0,0.01919139,0.01919139,-3.593417E-06,,,,,,100,-67.2251,-72.06754,,,,,,,,,,,,,,,,,,,,,48536448,0,1,6,1,,,,,,,,,,,,,,,,
Ch. 1 Input voltage exceeded compliance limit.,3899835707.74594,200.000869750977,64005.8515625,90,15.139,191.8329,0,-0.01113576,,,0.4359754,2.293708,0.1,0,0.01918169,0.01918169,-3.72807E-06,,,,,,100,-71.51904,-82.81433,,,,,,,,,,,,,,,,,,,,,48536448,0,1,6,1,,,,,,,,,,,,,,,,
Ch. 1 Input voltage exceeded compliance limit.,3899835728.89568,200.001129150391,62957.96875,90,15.143,191.9547,0,-0.01454002,,,0.4359754,2.293708,0.1,0,0.01919388,0.01919388,-4.870853E-06,,,,,,100,-58.83329,-68.14393,,,,,,,,,,,,,,,,,,,,,48536448,0,1,6,1,,,,,,,,,,,,,,,,
Ch. 1 Input voltage exceeded compliance limit.,3899835753.87836,200.001068115234,61718.2109375,90,15.135,191.9713,0,-0.01454455,,,0.4359754,2.293708,0.1,0,0.01919553,0.01919553,-4.87279E-06,,,,,,100,-77.41232,-63.42625,,,,,,,,,,,,,,,,,,,,,48536448,0,1,6,1,,,,,,,,,,,,,,,,
Ch. 1 Input voltage exceeded compliance limit.,3899835773.14095,200.000015258789,60774.45703125,90,15.14,192.0763,0,-0.01979642,,,0.4359754,2.293708,0.1,0,0.01920604,0.01920604,-6.635931E-06,,,,,,100,-74.47218,-74.50739,,,,,,,,,,,,,,,,,,,,,48536448,0,1,6,1,,,,,,,,,,,,,,,,
Ch. 1 Input voltage exceeded compliance limit.,3899835793.99828,200.001342773438,59741.37890625,90,15.154,192.4336,0,-0.01788657,,,0.4359754,2.293708,0.1,0,0.01924177,0.01924176,-6.006886E-06,,,,,,100,-81.86664,-69.37872,,,,,,,,,,,,,,,,,,,,,48536448,0,1,6,1,,,,,,,,,,,,,,,,
Ch. 1 Input voltage exceeded compliance limit.,3899835819.45952,200.000549316406,58481.6953125,90,15.156,192.4653,0,-0.03198202,,,0.4359754,2.293708,0.1,0,0.01924494,0.01924494,-1.074236E-05,,,,,,100,-67.02451,-66.00381,,,,,,,,,,,,,,,,,,,,,48536448,0,1,6,1,,,,,,,,,,,,,,,,
Ch. 1 Input voltage exceeded compliance limit.,3899835840.68504,200.000411987305,57434.46484375,90,15.143,192.6654,0,-0.02184056,,,0.4359754,2.293708,0.1,0,0.01926494,0.01926494,-7.343594E-06,,,,,,100,-67.82381,-74.35332,,,,,,,,,,,,,,,,,,,,,48536448,0,1,6,1,,,,,,,,,,,,,,,,
Ch. 1 Input voltage exceeded compliance limit.,3899835860.5673,200.001342773438,56451.296875,90,15.165,192.6714,0,-0.03759212,,,0.4359754,2.293708,0.1,0,0.01926554,0.01926554,-1.264024E-05,,,,,,100,-72.13492,-72.34267,,,,,,,,,,,,,,,,,,,,,48536448,0,1,6,1,,,,,,,,,,,,,,,,
Ch. 1 Input voltage exceeded compliance limit.,3899835881.29432,199.999160766602,55428.7578125,90,15.161,192.9439,0,-0.046673,,,0.4359754,2.293708,0.1,0,0.0192928,0.01929279,-1.571586E-05,,,,,,100,-64.21117,-61.19659,,,,,,,,,,,,,,,,,,,,,48536448,0,1,6,1,,,,,,,,,,,,,,,,
Ch. 1 Input voltage exceeded compliance limit.,3899835900.91698,199.998291015625,54460.61328125,90,15.159,192.6633,0,-0.02374327,,,0.4359754,2.293708,0.1,0,0.01926473,0.01926473,-7.98327E-06,,,,,,100,-62.12508,-74.74489,,,,,,,,,,,,,,,,,,,,,48536448,0,1,6,1,,,,,,,,,,,,,,,,
Ch. 1 Input voltage exceeded compliance limit.,3899835926.56506,200.000411987305,53196.0390625,90,15.17,192.7286,0,-0.0263222,,,0.4359754,2.293708,0.1,0,0.01927126,0.01927126,-8.85339E-06,,,,,,100,-59.00442,-78.48738,,,,,,,,,,,,,,,,,,,,,48536448,0,1,6,1,,,,,,,,,,,,,,,,
Ch. 1 Input voltage exceeded compliance limit.,3899835947.50093,199.999221801758,52158.63671875,90,15.167,193.2231,0,-0.02791384,,,0.4359754,2.293708,0.1,0,0.01932071,0.01932071,-9.412825E-06,,,,,,100,-73.00645,-66.6373,,,,,,,,,,,,,,,,,,,,,48536448,0,1,6,1,,,,,,,,,,,,,,,,
Ch. 1 Input voltage exceeded compliance limit.,3899835967.39044,200.001129150391,51172.69921875,90,15.16,193.6562,0,-0.05493268,,,0.4359754,2.293708,0.1,0,0.01936402,0.01936401,-1.856537E-05,,,,,,100,-71.74815,-67.13702,,,,,,,,,,,,,,,,,,,,,48536448,0,1,6,1,,,,,,,,,,,,,,,,
Ch. 1 Input voltage exceeded compliance limit.,3899835987.92935,200.000076293945,50152.34375,90,15.156,193.4339,0,-0.05372328,,,0.4359754,2.293708,0.1,0,0.01934179,0.01934178,-1.813579E-05,,,,,,100,-62.72589,-63.83039,,,,,,,,,,,,,,,,,,,,,48536448,0,1,6,1,,,,,,,,,,,,,,,,
Ch. 1 Input voltage exceeded compliance limit.,3899836012.64876,199.998748779297,48912.55859375,90,15.148,193.9589,0,-0.03080248,,,0.4359754,2.293708,0.1,0,0.01939429,0.01939428,-1.042646E-05,,,,,,100,-67.23615,-79.50978,,,,,,,,,,,,,,,,,,,,,48536448,0,1,6,1,,,,,,,,,,,,,,,,
Ch. 1 Input voltage exceeded compliance limit.,3899836033.78937,200.000732421875,47862.59765625,90,15.133,193.8213,0,-0.0142987,,,0.4359754,2.293708,0.1,0,0.01938052,0.01938052,-4.83659E-06,,,,,,100,-62.80662,-66.46239,,,,,,,,,,,,,,,,,,,,,48536448,0,1,6,1,,,,,,,,,,,,,,,,
Ch. 1 Input voltage exceeded compliance limit.,3899836053.17722,200.001266479492,46901.89453125,90,15.139,193.8433,0,-0.04513503,,,0.4359754,2.293708,0.1,0,0.01938272,0.01938272,-1.526883E-05,,,,,,100,-70.49609,-72.45033,,,,,,,,,,,,,,,,,,,,,48536448,0,1,6,1,,,,,,,,,,,,,,,,
Ch. 1 Input voltage exceeded compliance limit.,3899836078.01051,200.000411987305,45666.6953125,90,15.144,193.9596,0,-0.04369275,,,0.4359754,2.293708,0.1,0,0.01939436,0.01939435,-1.478979E-05,,,,,,100,-61.6865,-66.10722,,,,,,,,,,,,,,,,,,,,,48536448,0,1,6,1,,,,,,,,,,,,,,,,
Ch. 1 Input voltage exceeded compliance limit.,3899836098.83882,200.000274658203,44626.59765625,90,15.138,194.1115,0,-0.02435428,,,0.4359754,2.293708,0.1,0,0.01940954,0.01940954,-8.250266E-06,,,,,,100,-63.54874,-67.14616,,,,,,,,,,,,,,,,,,,,,48536448,0,1,6,1,,,,,,,,,,,,,,,,
Ch. 1 Input voltage exceeded compliance limit.,3899836119.26381,200.001129150391,43611.21875,90,15.133,194.2817,0,-0.02256832,,,0.4359754,2.293708,0.1,0,0.01942655,0.01942655,-7.651953E-06,,,,,,100,-66.75864,-66.84759,,,,,,,,,,,,,,,,,,,,,48536448,0,1,6,1,,,,,,,,,,,,,,,,
Ch. 1 Input voltage exceeded compliance limit.,3899836140.035,200.001129150391,42575.9921875,90,15.135,194.2984,0,-0.00696656,,,0.4359754,2.293708,0.1,0,0.01942823,0.01942823,-2.362267E-06,,,,,,100,-70.60378,-60.53873,,,,,,,,,,,,,,,,,,,,,48536448,0,1,6,1,,,,,,,,,,,,,,,,
Ch. 1 Input voltage exceeded compliance limit.,3899836159.73848,200.001724243164,41595.6796875,90,15.132,195.0953,0,-0.03189278,,,0.4359754,2.293708,0.1,0,0.01950791,0.01950791,-1.085877E-05,,,,,,100,-62.98155,-65.49571,,,,,,,,,,,,,,,,,,,,,48536448,0,1,6,1,,,,,,,,,,,,,,,,
Ch. 1 Input voltage exceeded compliance limit.,3899836180.60873,200.000869750977,40555.69921875,90,15.119,195.0534,0,-0.02421128,,,0.4359754,2.293708,0.1,0,0.01950372,0.01950372,-8.241618E-06,,,,,,100,-72.38335,-68.60819,,,,,,,,,,,,,,,,,,,,,48536448,0,1,6,1,,,,,,,,,,,,,,,,
Ch. 1 Input voltage exceeded compliance limit.,3899836205.56136,200.001129150391,39316.20703125,90,15.095,195.271,0,-0.02600923,,,0.4359754,2.293708,0.1,0,0.01952548,0.01952548,-8.863527E-06,,,,,,100,-67.14814,-73.92898,,,,,,,,,,,,,,,,,,,,,48536448,0,1,6,1,,,,,,,,,,,,,,,,
Ch. 1 Input voltage exceeded compliance limit.,3899836225.57666,200.001342773438,38321.015625,90,15.093,195.3868,0,-0.02071179,,,0.4359754,2.293708,0.1,0,0.01953706,0.01953706,-7.062431E-06,,,,,,100,-64.29073,-69.33798,,,,,,,,,,,,,,,,,,,,,48536448,0,1,6,1,,,,,,,,,,,,,,,,
Ch. 1 Input voltage exceeded compliance limit.,3899836246.53829,199.999618530273,37275.8046875,90,15.096,195.6087,0,-0.0363056,,,0.4359754,2.293708,0.1,0,0.01955925,0.01955925,-1.239376E-05,,,,,,100,-60.95232,-69.09272,,,,,,,,,,,,,,,,,,,,,48536448,0,1,6,1,,,,,,,,,,,,,,,,
Ch. 1 Input voltage exceeded compliance limit.,3899836265.97334,200.001129150391,36310.33984375,90,15.115,195.9843,0,-0.02621619,,,0.4359754,2.293708,0.1,0,0.01959681,0.01959681,-8.966692E-06,,,,,,100,-61.96202,-71.08224,,,,,,,,,,,,,,,,,,,,,48536448,0,1,6,1,,,,,,,,,,,,,,,,
Ch. 1 Input voltage exceeded compliance limit.,3899836287.33942,200.000869750977,35244.75,90,15.106,196.235,0,-0.03268448,,,0.4359754,2.293708,0.1,0,0.01962188,0.01962187,-1.119333E-05,,,,,,100,-64.42739,-70.39489,,,,,,,,,,,,,,,,,,,,,48536448,0,1,6,1,,,,,,,,,,,,,,,,
Ch. 1 Input voltage exceeded compliance limit.,3899836306.82188,200.000732421875,34274.33203125,90,15.106,196.34,0,-0.04507389,,,0.4359754,2.293708,0.1,0,0.01963237,0.01963237,-1.544454E-05,,,,,,100,-62.52567,-60.18209,,,,,,,,,,,,,,,,,,,,,48536448,0,1,6,1,,,,,,,,,,,,,,,,
Ch. 1 Input voltage exceeded compliance limit.,3899836327.78802,200.001525878906,33234.0390625,90,15.107,196.588,0,-0.02468891,,,0.4359754,2.293708,0.1,0,0.01965717,0.01965717,-8.470331E-06,,,,,,100,-67.31444,-87.58275,,,,,,,,,,,,,,,,,,,,,48536448,0,1,6,1,,,,,,,,,,,,,,,,
Ch. 1 Input voltage exceeded compliance limit.,3899836347.58966,200.001068115234,32243.51171875,90,15.112,196.3727,0,-0.01892953,,,0.4359754,2.293708,0.1,0,0.01963564,0.01963564,-6.487274E-06,,,,,,100,-66.55358,-66.4581,,,,,,,,,,,,,,,,,,,,,48536448,0,1,6,1,,,,,,,,,,,,,,,,
Ch. 1 Input voltage exceeded compliance limit.,3899836368.68921,200.001724243164,31197.634765625,90,15.11,196.5031,0,-0.02470331,,,0.4359754,2.293708,0.1,0,0.01964868,0.01964868,-8.471608E-06,,,,,,100,-68.49452,-68.07498,,,,,,,,,,,,,,,,,,,,,48536448,0,1,6,1,,,,,,,,,,,,,,,,
Ch. 1 Input voltage exceeded compliance limit.,3899836393.50801,200.001403808594,29958.611328125,90,15.116,196.7737,0,-0.04042134,,,0.4359754,2.293708,0.1,0,0.01967574,0.01967574,-1.388095E-05,,,,,,100,-75.2888,-66.48166,,,,,,,,,,,,,,,,,,,,,48536448,0,1,6,1,,,,,,,,,,,,,,,,
Ch. 1 Input voltage exceeded compliance limit.,3899836413.47242,199.999557495117,28968.16015625,90,15.135,196.8287,0,-0.02834315,,,0.4359754,2.293708,0.1,0,0.01968124,0.01968123,-9.735939E-06,,,,,,100,-70.05347,-66.88597,,,,,,,,,,,,,,,,,,,,,48536448,0,1,6,1,,,,,,,,,,,,,,,,
Ch. 1 Input voltage exceeded compliance limit.,3899836434.90328,200.001129150391,27898.076171875,90,15.14,196.8204,0,-0.03980907,,,0.4359754,2.293708,0.1,0,0.01968041,0.01968041,-1.367394E-05,,,,,,100,-57.7492,-65.80464,,,,,,,,,,,,,,,,,,,,,48536448,0,1,6,1,,,,,,,,,,,,,,,,
Ch. 1 Input voltage exceeded compliance limit.,3899836454.80829,200.001266479492,26907.677734375,90,15.145,196.5421,0,-0.01651842,,,0.4359754,2.293708,0.1,0,0.01965258,0.01965258,-5.665854E-06,,,,,,100,-62.68497,-62.85853,,,,,,,,,,,,,,,,,,,,,48536448,0,1,6,1,,,,,,,,,,,,,,,,
Ch. 1 Input voltage exceeded compliance limit.,3899836475.98484,200.001129150391,25852.908203125,90,15.154,197.3135,0,-0.01880044,,,0.4359754,2.293708,0.1,0,0.01972971,0.01972971,-6.473902E-06,,,,,,100,-64.81308,-65.38117,,,,,,,,,,,,,,,,,,,,,48536448,0,1,6,1,,,,,,,,,,,,,,,,
Ch. 1 Input voltage exceeded compliance limit.,3899836501.19017,200.001724243164,24594.439453125,90,15.173,197.8052,0,-0.03809787,,,0.4359754,2.293708,0.1,0,0.01977888,0.01977888,-1.315163E-05,,,,,,100,-62.46864,-65.2098,,,,,,,,,,,,,,,,,,,,,48536448,0,1,6,1,,,,,,,,,,,,,,,,
Ch. 1 Input voltage exceeded compliance limit.,3899836522.3023,200.001266479492,23540.28515625,90,15.176,198.181,0,-0.0396559,,,0.4359754,2.293708,0.1,0,0.01981646,0.01981646,-1.371549E-05,,,,,,100,-59.99362,-61.68496,,,,,,,,,,,,,,,,,,,,,48536448,0,1,6,1,,,,,,,,,,,,,,,,
Ch. 1 Input voltage exceeded compliance limit.,3899836542.17256,200.001525878906,22551.376953125,90,15.174,198.096,0,-0.009338764,,,0.4359754,2.293708,0.1,0,0.01980795,0.01980795,-3.228542E-06,,,,,,100,-68.854,-61.13077,,,,,,,,,,,,,,,,,,,,,48536448,0,1,6,1,,,,,,,,,,,,,,,,
Ch. 1 Input voltage exceeded compliance limit.,3899836562.06874,200.001129150391,21557.326171875,90,15.173,198.0804,0,-0.02480077,,,0.4359754,2.293708,0.1,0,0.0198064,0.0198064,-8.573303E-06,,,,,,100,-63.32851,-62.52422,,,,,,,,,,,,,,,,,,,,,48536448,0,1,6,1,,,,,,,,,,,,,,,,
Ch. 1 Input voltage exceeded compliance limit.,3899836583.29074,200.001068115234,20492.7421875,90,15.211,197.9346,0,-0.05700044,,,0.4359754,2.293708,0.1,0,0.01979183,0.01979182,-1.968981E-05,,,,,,100,-61.54131,-58.37067,,,,,,,,,,,,,,,,,,,,,48536448,0,1,6,1,,,,,,,,,,,,,,,,
Ch. 1 Input voltage exceeded compliance limit.,3899836608.74354,199.999221801758,19224.28125,90,15.213,198.3152,0,-0.04854355,,,0.4359754,2.293708,0.1,0,0.01982989,0.01982988,-1.680076E-05,,,,,,100,-65.30843,-64.16979,,,,,,,,,,,,,,,,,,,,,48536448,0,1,6,1,,,,,,,,,,,,,,,,
Ch. 1 Input voltage exceeded compliance limit.,3899836630.17162,199.999557495117,18154.947265625,90,15.208,199.0595,0,-0.02265462,,,0.4359754,2.293708,0.1,0,0.0199043,0.0199043,-7.870112E-06,,,,,,100,-63.945,-73.39857,,,,,,,,,,,,,,,,,,,,,48536448,0,1,6,1,,,,,,,,,,,,,,,,
Ch. 1 Input voltage exceeded compliance limit.,3899836655.11499,200.001403808594,16905.587890625,90,15.204,199.2212,0,-0.04314662,,,0.4359754,2.293708,0.1,0,0.01992047,0.01992046,-1.500112E-05,,,,,,100,-68.99316,-62.70843,,,,,,,,,,,,,,,,,,,,,48536448,0,1,6,1,,,,,,,,,,,,,,,,
Ch. 1 Input voltage exceeded compliance limit.,3899836674.82921,200.001266479492,15921.5244140625,90,15.219,198.9658,0,-0.008505993,,,0.4359754,2.293708,0.1,0,0.01989493,0.01989493,-2.953553E-06,,,,,,100,-57.60933,-61.73141,,,,,,,,,,,,,,,,,,,,,48536448,0,1,6,1,,,,,,,,,,,,,,,,
Ch. 1 Input voltage exceeded compliance limit.,3899836695.62343,200.001129150391,14882.58984375,90,15.234,199.5564,0,-0.03733365,,,0.4359754,2.293708,0.1,0,0.01995399,0.01995399,-1.300192E-05,,,,,,100,-65.44976,-72.99219,,,,,,,,,,,,,,,,,,,,,48536448,0,1,6,1,,,,,,,,,,,,,,,,
Ch. 1 Input voltage exceeded compliance limit.,3899836720.68151,199.999160766602,13624.0703125,90,15.243,199.5998,0,-0.01158819,,,0.4359754,2.293708,0.1,0,0.01995832,0.01995832,-4.036614E-06,,,,,,100,-66.45712,-64.70142,,,,,,,,,,,,,,,,,,,,,48536448,0,1,6,1,,,,,,,,,,,,,,,,
Ch. 1 Input voltage exceeded compliance limit.,3899836741.69862,200.001266479492,12579.921875,90,15.234,200.0033,0,-0.03403804,,,0.4359754,2.293708,0.1,0,0.01999867,0.01999866,-1.188072E-05,,,,,,100,-63.57585,-66.08888,,,,,,,,,,,,,,,,,,,,,48536448,0,1,6,1,,,,,,,,,,,,,,,,
Ch. 1 Input voltage exceeded compliance limit.,3899836761.40979,200.000274658203,11596.2939453125,90,15.239,200.0839,0,-0.02375757,,,0.4359754,2.293708,0.1,0,0.02000673,0.02000673,-8.295748E-06,,,,,,100,-76.89515,-72.45291,,,,,,,,,,,,,,,,,,,,,48536448,0,1,6,1,,,,,,,,,,,,,,,,
Ch. 1 Input voltage exceeded compliance limit.,3899836782.45153,200.001525878906,10542.25390625,90,15.229,200.3858,0,-0.02015034,,,0.4359754,2.293708,0.1,0,0.02003692,0.02003692,-7.04678E-06,,,,,,100,-67.06071,-75.43196,,,,,,,,,,,,,,,,,,,,,48536448,0,1,6,1,,,,,,,,,,,,,,,,
Ch. 1 Input voltage exceeded compliance limit.,3899836802.07298,200.001068115234,9563.2607421875,90,15.251,200.4374,0,-0.03852487,,,0.4359754,2.293708,0.1,0,0.02004208,0.02004207,-1.347601E-05,,,,,,100,-61.70152,-69.03991,,,,,,,,,,,,,,,,,,,,,48536448,0,1,6,1,,,,,,,,,,,,,,,,
Ch. 1 Input voltage exceeded compliance limit.,3899836823.2013,200.000076293945,8509.728515625,90,15.251,200.5537,0,-0.01845686,,,0.4359754,2.293708,0.1,0,0.02005371,0.0200537,-6.459959E-06,,,,,,100,-63.03722,-63.35827,,,,,,,,,,,,,,,,,,,,,48536448,0,1,6,1,,,,,,,,,,,,,,,,
Ch. 1 Input voltage exceeded compliance limit.,3899836842.94493,200.001129150391,7520.615234375,90,15.251,200.8061,0,-0.04555105,,,0.4359754,2.293708,0.1,0,0.02007895,0.02007894,-1.596308E-05,,,,,,100,-58.28731,-68.0145,,,,,,,,,,,,,,,,,,,,,48536448,0,1,6,1,,,,,,,,,,,,,,,,
Ch. 1 Input voltage exceeded compliance limit.,3899836862.81884,200.000671386719,6530.9052734375,90,15.253,200.7341,0,-0.02733925,,,0.4359754,2.293708,0.1,0,0.02007175,0.02007175,-9.577432E-06,,,,,,100,-68.27916,-71.15093,,,,,,,,,,,,,,,,,,,,,48536448,0,1,6,1,,,,,,,,,,,,,,,,
Ch. 1 Input voltage exceeded compliance limit.,3899836884.01604,200.000671386719,5471.931640625,90,15.253,200.8658,0,-0.02883143,,,0.4359754,2.293708,0.1,0,0.02008491,0.02008491,-1.010679E-05,,,,,,100,-73.21544,-67.21391,,,,,,,,,,,,,,,,,,,,,48536448,0,1,6,1,,,,,,,,,,,,,,,,
Ch. 1 Input voltage exceeded compliance limit.,3899836903.67629,200.000549316406,4488.068359375,90,15.256,201.0045,0,-0.04020038,,,0.4359754,2.293708,0.1,0,0.02009879,0.02009878,-1.410189E-05,,,,,,100,-58.47872,-62.07264,,,,,,,,,,,,,,,,,,,,,48536448,0,1,6,1,,,,,,,,,,,,,,,,
Ch. 1 Input voltage exceeded compliance limit.,3899836924.84029,200.000671386719,3428.5107421875,90,15.265,201.3376,0,-0.03119249,,,0.4359754,2.293708,0.1,0,0.02013209,0.02013209,-1.096015E-05,,,,,,100,-59.27811,-72.24966,,,,,,,,,,,,,,,,,,,,,48536448,0,1,6,1,,,,,,,,,,,,,,,,
Ch. 1 Input voltage exceeded compliance limit.,3899836944.69347,199.998748779297,2438.89624023438,90,15.256,201.3946,0,-0.01927317,,,0.4359754,2.293708,0.1,0,0.02013779,0.02013778,-6.773955E-06,,,,,,100,-67.74907,-73.41317,,,,,,,,,,,,,,,,,,,,,48536448,0,1,6,1,,,,,,,,,,,,,,,,
Ch. 1 Input voltage exceeded compliance limit.,3899836965.60658,200.000671386719,1394.5458984375,90,15.251,201.3439,0,-0.0172009,,,0.4359754,2.293708,0.1,0,0.02013272,0.02013272,-6.044091E-06,,,,,,100,-62.86388,-62.77983,,,,,,,,,,,,,,,,,,,,,48536448,0,1,6,1,,,,,,,,,,,,,,,,
Ch. 1 Input voltage exceeded compliance limit.,3899836985.31934,200.001129150391,409.586456298828,90,15.267,201.914,0,-0.03724001,,,0.4359754,2.293708,0.1,0,0.02018973,0.02018972,-1.312253E-05,,,,,,100,-65.40879,-64.94344,,,,,,,,,,,,,,,,,,,,,48536448,0,1,6,1,,,,,,,,,,,,,,,,
Ch. 1 Input voltage exceeded compliance limit.,3899837006.5416,200.001068115234,-650.139526367188,90,15.257,202.2088,0,-0.01300043,,,0.4359754,2.293708,0.1,0,0.0202192,0.0202192,-4.587744E-06,,,,,,100,-71.02292,-64.44183,,,,,,,,,,,,,,,,,,,,,48536448,0,1,6,1,,,,,,,,,,,,,,,,
Ch. 1 Input voltage exceeded compliance limit.,3899837031.61566,200.001602172852,-1903.58178710938,90,15.251,202.448,0,-0.02168888,,,0.4359754,2.293708,0.1,0,0.02024312,0.02024312,-7.662878E-06,,,,,,100,-64.23841,-69.13924,,,,,,,,,,,,,,,,,,,,,48536448,0,1,6,1,,,,,,,,,,,,,,,,
Ch. 1 Input voltage exceeded compliance limit.,3899837051.57152,200.001266479492,-2902.8056640625,90,15.238,202.1971,0,-0.02752829,,,0.4359754,2.293708,0.1,0,0.02021804,0.02021804,-9.713944E-06,,,,,,100,-61.01293,-69.40144,,,,,,,,,,,,,,,,,,,,,48536448,0,1,6,1,,,,,,,,,,,,,,,,
Ch. 1 Input voltage exceeded compliance limit.,3899837072.66483,200.001129150391,-3958.0087890625,90,15.233,202.4388,0,-0.03085029,,,0.4359754,2.293708,0.1,0,0.0202422,0.0202422,-1.08992E-05,,,,,,100,-59.10997,-74.41276,,,,,,,,,,,,,,,,,,,,,48536448,0,1,6,1,,,,,,,,,,,,,,,,
Ch. 1 Input voltage exceeded compliance limit.,3899837092.24451,200.000869750977,-4938.7734375,90,15.227,202.4232,0,-0.02921956,,,0.4359754,2.293708,0.1,0,0.02024064,0.02024064,-1.032227E-05,,,,,,100,-79.08116,-63.59327,,,,,,,,,,,,,,,,,,,,,48536448,0,1,6,1,,,,,,,,,,,,,,,,
Ch. 1 Input voltage exceeded compliance limit.,3899837113.46929,200.000869750977,-5997.78662109375,90,15.237,202.2609,0,-0.02978791,,,0.4359754,2.293708,0.1,0,0.02022441,0.02022441,-1.051461E-05,,,,,,100,-54.30898,-60.94174,,,,,,,,,,,,,,,,,,,,,48536448,0,1,6,1,,,,,,,,,,,,,,,,
Ch. 1 Input voltage exceeded compliance limit.,3899837132.9591,200.000869750977,-6968.052734375,90,15.228,202.1487,0,-0.02946936,,,0.4359754,2.293708,0.1,0,0.02021319,0.02021319,-1.03964E-05,,,,,,100,-62.41976,-72.58965,,,,,,,,,,,,,,,,,,,,,48536448,0,1,6,1,,,,,,,,,,,,,,,,
Ch. 1 Input voltage exceeded compliance limit.,3899837154.24143,200.000869750977,-8039.439453125,90,15.228,202.7326,0,-0.02392619,,,0.4359754,2.293708,0.1,0,0.02027158,0.02027158,-8.465225E-06,,,,,,100,-69.84103,-85.09385,,,,,,,,,,,,,,,,,,,,,48536448,0,1,6,1,,,,,,,,,,,,,,,,
Ch. 1 Input voltage exceeded compliance limit.,3899837173.84602,200.000549316406,-9020.0185546875,90,15.234,202.3564,0,-0.01788344,,,0.4359754,2.293708,0.1,0,0.02023396,0.02023396,-6.315523E-06,,,,,,100,-73.02052,-66.72133,,,,,,,,,,,,,,,,,,,,,48536448,0,1,6,1,,,,,,,,,,,,,,,,
Ch. 1 Input voltage exceeded compliance limit.,3899837194.71801,200.001266479492,-10060.8203125,90,15.248,202.5104,0,-0.03748845,,,0.4359754,2.293708,0.1,0,0.02024936,0.02024936,-1.324909E-05,,,,,,100,-63.78817,-72.36224,,,,,,,,,,,,,,,,,,,,,48536448,0,1,6,1,,,,,,,,,,,,,,,,
Ch. 1 Input voltage exceeded compliance limit.,3899837220.06628,200.000411987305,-11332.6689453125,90,15.252,202.2464,0,-0.05226018,,,0.4359754,2.293708,0.1,0,0.02022297,0.02022296,-1.844561E-05,,,,,,100,-60.34705,-60.26415,,,,,,,,,,,,,,,,,,,,,48536448,0,1,6,1,,,,,,,,,,,,,,,,
Ch. 1 Input voltage exceeded compliance limit.,3899837239.94912,200.000274658203,-12328.4541015625,90,15.256,202.2182,0,-0.02998846,,,0.4359754,2.293708,0.1,0,0.02022014,0.02022014,-1.058317E-05,,,,,,100,-62.85281,-60.96197,,,,,,,,,,,,,,,,,,,,,48536448,0,1,6,1,,,,,,,,,,,,,,,,
Ch. 1 Input voltage exceeded compliance limit.,3899837261.00083,199.9990234375,-13379.880859375,90,15.247,202.4706,0,-0.02550842,,,0.4359754,2.293708,0.1,0,0.02024538,0.02024538,-9.013362E-06,,,,,,100,-64.72154,-68.99541,,,,,,,,,,,,,,,,,,,,,48536448,0,1,6,1,,,,,,,,,,,,,,,,
Ch. 1 Input voltage exceeded compliance limit.,3899837280.65402,199.999557495117,-14367.5302734375,90,15.256,202.4382,0,-0.01274806,,,0.4359754,2.293708,0.1,0,0.02024213,0.02024213,-4.503785E-06,,,,,,100,-66.64095,-64.10892,,,,,,,,,,,,,,,,,,,,,48536448,0,1,6,1,,,,,,,,,,,,,,,,
Ch. 1 Input voltage exceeded compliance limit.,3899837302.09028,200.000076293945,-15440.04296875,90,15.24,202.5026,0,-0.02176963,,,0.4359754,2.293708,0.1,0,0.02024858,0.02024858,-7.693484E-06,,,,,,100,-61.80946,-65.62581,,,,,,,,,,,,,,,,,,,,,48536448,0,1,6,1,,,,,,,,,,,,,,,,
Ch. 1 Input voltage exceeded compliance limit.,3899837326.8756,200.000549316406,-16688.115234375,90,15.238,202.5721,0,-0.02760408,,,0.4359754,2.293708,0.1,0,0.02025553,0.02025553,-9.758753E-06,,,,,,100,-66.10421,-65.76529,,,,,,,,,,,,,,,,,,,,,48536448,0,1,6,1,,,,,,,,,,,,,,,,
Ch. 1 Input voltage exceeded compliance limit.,3899837348.27273,200.001602172852,-17755.86328125,90,15.241,202.6747,0,-0.02819892,,,0.4359754,2.293708,0.1,0,0.02026579,0.02026579,-9.97409E-06,,,,,,100,-70.71517,-63.24169,,,,,,,,,,,,,,,,,,,,,48536448,0,1,6,1,,,,,,,,,,,,,,,,
Ch. 1 Input voltage exceeded compliance limit.,3899837367.56999,200.001266479492,-18723.35546875,90,15.218,202.609,0,-0.01849272,,,0.4359754,2.293708,0.1,0,0.02025922,0.02025922,-6.538842E-06,,,,,,100,-72.91406,-69.48026,,,,,,,,,,,,,,,,,,,,,48536448,0,1,6,1,,,,,,,,,,,,,,,,
Ch. 1 Input voltage exceeded compliance limit.,3899837387.32599,200.000732421875,-19715.720703125,90,15.204,202.544,0,-0.01725971,,,0.4359754,2.293708,0.1,0,0.02025272,0.02025272,-6.100905E-06,,,,,,100,-65.2356,-69.63417,,,,,,,,,,,,,,,,,,,,,48536448,0,1,6,1,,,,,,,,,,,,,,,,
Ch. 1 Input voltage exceeded compliance limit.,3899837408.36029,200.000015258789,-20768.18359375,90,15.197,202.7884,0,-0.01775952,,,0.4359754,2.293708,0.1,0,0.02027716,0.02027716,-6.285151E-06,,,,,,100,-55.38923,-62.18669,,,,,,,,,,,,,,,,,,,,,48536448,0,1,6,1,,,,,,,,,,,,,,,,
Ch. 1 Input voltage exceeded compliance limit.,3899837427.94508,199.999221801758,-21751.333984375,90,15.177,202.5705,0,-0.02806606,,,0.4359754,2.293708,0.1,0,0.02025537,0.02025537,-9.921996E-06,,,,,,100,-60.84432,-67.62123,,,,,,,,,,,,,,,,,,,,,48536448,0,1,6,1,,,,,,,,,,,,,,,,
Ch. 1 Input voltage exceeded compliance limit.,3899837449.30501,200.001266479492,-22824.177734375,90,15.174,202.4311,0,-0.03171076,,,0.4359754,2.293708,0.1,0,0.02024144,0.02024143,-1.120277E-05,,,,,,100,-68.41211,-68.69266,,,,,,,,,,,,,,,,,,,,,48536448,0,1,6,1,,,,,,,,,,,,,,,,
Ch. 1 Input voltage exceeded compliance limit.,3899837468.77531,199.999618530273,-23796.3984375,90,15.165,202.2323,0,-0.006340772,,,0.4359754,2.293708,0.1,0,0.02022155,0.02022155,-2.237866E-06,,,,,,100,-77.94711,-67.08335,,,,,,,,,,,,,,,,,,,,,48536448,0,1,6,1,,,,,,,,,,,,,,,,
Ch. 1 Input voltage exceeded compliance limit.,3899837490.04288,199.999557495117,-24864.08984375,90,15.141,202.7081,0,-0.02118467,,,0.4359754,2.293708,0.1,0,0.02026912,0.02026912,-7.494352E-06,,,,,,100,-69.22113,-58.19395,,,,,,,,,,,,,,,,,,,,,48536448,0,1,6,1,,,,,,,,,,,,,,,,
Ch. 1 Input voltage exceeded compliance limit.,3899837515.34809,199.999816894531,-26132.9453125,90,15.156,202.4095,0,-0.03033413,,,0.4359754,2.293708,0.1,0,0.02023927,0.02023927,-1.071528E-05,,,,,,100,-64.43676,-71.17911,,,,,,,,,,,,,,,,,,,,,48536448,0,1,6,1,,,,,,,,,,,,,,,,
Ch. 1 Input voltage exceeded compliance limit.,3899837536.7449,200.001403808594,-27205.7734375,90,15.147,202.7297,0,-0.02745317,,,0.4359754,2.293708,0.1,0,0.02027129,0.02027129,-9.712952E-06,,,,,,100,-60.44845,-70.81664,,,,,,,,,,,,,,,,,,,,,48536448,0,1,6,1,,,,,,,,,,,,,,,,
Ch. 1 Input voltage exceeded compliance limit.,3899837556.68041,200.001068115234,-28208.2578125,90,15.161,202.7794,0,-0.01751896,,,0.4359754,2.293708,0.1,0,0.02027626,0.02027626,-6.199743E-06,,,,,,100,-66.68812,-61.38128,,,,,,,,,,,,,,,,,,,,,48536448,0,1,6,1,,,,,,,,,,,,,,,,
Ch. 1 Input voltage exceeded compliance limit.,3899837576.29107,200.001342773438,-29190.583984375,90,15.167,202.7201,0,-0.03354016,,,0.4359754,2.293708,0.1,0,0.02027033,0.02027033,-1.186597E-05,,,,,,100,-61.92996,-65.8364,,,,,,,,,,,,,,,,,,,,,48536448,0,1,6,1,,,,,,,,,,,,,,,,
Ch. 1 Input voltage exceeded compliance limit.,3899837597.85569,200.000869750977,-30268.396484375,90,15.186,203.3551,0,-0.0331009,,,0.4359754,2.293708,0.1,0,0.02033383,0.02033383,-1.174725E-05,,,,,,100,-56.50279,-63.68441,,,,,,,,,,,,,,,,,,,,,48536448,0,1,6,1,,,,,,,,,,,,,,,,
Ch. 1 Input voltage exceeded compliance limit.,3899837617.74384,200.000274658203,-31265.833984375,90,15.191,203.2321,0,-0.02718562,,,0.4359754,2.293708,0.1,0,0.02032153,0.02032152,-9.642128E-06,,,,,,100,-69.21368,-66.57817,,,,,,,,,,,,,,,,,,,,,48536448,0,1,6,1,,,,,,,,,,,,,,,,
Ch. 1 Input voltage exceeded compliance limit.,3899837638.81295,199.999618530273,-32323.369140625,90,15.222,203.0642,0,-0.01707644,,,0.4359754,2.293708,0.1,0,0.02030474,0.02030474,-6.051627E-06,,,,,,100,-64.51276,-60.3964,,,,,,,,,,,,,,,,,,,,,48536448,0,1,6,1,,,,,,,,,,,,,,,,
Ch. 1 Input voltage exceeded compliance limit.,3899837664.33356,200.000869750977,-33601.703125,90,15.23,203.388,0,-0.02745693,,,0.4359754,2.293708,0.1,0,0.02033712,0.02033711,-9.745826E-06,,,,,,100,-64.74384,-75.0677,,,,,,,,,,,,,,,,,,,,,48536448,0,1,6,1,,,,,,,,,,,,,,,,
Ch. 1 Input voltage exceeded compliance limit.,3899837685.0616,200.001129150391,-34639.21875,90,15.27,203.3632,0,-0.04218092,,,0.4359754,2.293708,0.1,0,0.02033464,0.02033463,-1.497027E-05,,,,,,100,-63.67903,-61.72035,,,,,,,,,,,,,,,,,,,,,48536448,0,1,6,1,,,,,,,,,,,,,,,,
Ch. 1 Input voltage exceeded compliance limit.,3899837705.10188,199.999877929688,-35647.421875,90,15.27,203.3814,0,-0.03683098,,,0.4359754,2.293708,0.1,0,0.02033646,0.02033645,-1.307272E-05,,,,,,100,-63.27538,-64.26836,,,,,,,,,,,,,,,,,,,,,48536448,0,1,6,1,,,,,,,,,,,,,,,,
Ch. 1 Input voltage exceeded compliance limit.,3899837724.75797,199.999420166016,-36635.03125,90,15.265,203.1307,0,-0.02884719,,,0.4359754,2.293708,0.1,0,0.02031139,0.02031138,-1.022635E-05,,,,,,100,-67.47456,-58.14917,,,,,,,,,,,,,,,,,,,,,48536448,0,1,6,1,,,,,,,,,,,,,,,,
Ch. 1 Input voltage exceeded compliance limit.,3899837745.84972,199.999816894531,-37692.51953125,90,15.264,203.612,0,-0.04932888,,,0.4359754,2.293708,0.1,0,0.02035951,0.0203595,-1.752855E-05,,,,,,100,-57.69875,-61.37888,,,,,,,,,,,,,,,,,,,,,48536448,0,1,6,1,,,,,,,,,,,,,,,,
Ch. 1 Input voltage exceeded compliance limit.,3899837770.996,200.000869750977,-38950.765625,90,15.314,203.6475,0,-0.04479163,,,0.4359754,2.293708,0.1,0,0.02036307,0.02036306,-1.591906E-05,,,,,,100,-64.05017,-74.96756,,,,,,,,,,,,,,,,,,,,,48536448,0,1,6,1,,,,,,,,,,,,,,,,
Ch. 1 Input voltage exceeded compliance limit.,3899837792.1518,200.000869750977,-40014.1796875,90,15.294,203.7581,0,-0.02360997,,,0.4359754,2.293708,0.1,0,0.02037412,0.02037412,-8.3956E-06,,,,,,100,-69.16676,-65.5475,,,,,,,,,,,,,,,,,,,,,48536448,0,1,6,1,,,,,,,,,,,,,,,,
Ch. 1 Input voltage exceeded compliance limit.,3899837811.7773,200.001266479492,-40996.56640625,90,15.29,203.6851,0,-0.04008696,,,0.4359754,2.293708,0.1,0,0.02036683,0.02036682,-1.424964E-05,,,,,,100,-63.6356,-73.77095,,,,,,,,,,,,,,,,,,,,,48536448,0,1,6,1,,,,,,,,,,,,,,,,
Ch. 1 Input voltage exceeded compliance limit.,3899837833.15951,200.001129150391,-42064.16796875,90,15.287,203.5772,0,-0.02541135,,,0.4359754,2.293708,0.1,0,0.02035603,0.02035603,-9.028137E-06,,,,,,100,-72.00454,-62.8026,,,,,,,,,,,,,,,,,,,,,48536448,0,1,6,1,,,,,,,,,,,,,,,,
Ch. 1 Input voltage exceeded compliance limit.,3899837853.146,200.000076293945,-43066.859375,90,15.305,203.9501,0,-0.05075103,,,0.4359754,2.293708,0.1,0,0.02039333,0.02039332,-1.806385E-05,,,,,,100,-71.99744,-66.12744,,,,,,,,,,,,,,,,,,,,,48536448,0,1,6,1,,,,,,,,,,,,,,,,
Ch. 1 Input voltage exceeded compliance limit.,3899837878.29057,199.999221801758,-44329.953125,90,15.296,203.5582,0,-0.0458488,,,0.4359754,2.293708,0.1,0,0.02035413,0.02035413,-1.628763E-05,,,,,,100,-61.91659,-78.77779,,,,,,,,,,,,,,,,,,,,,48536448,0,1,6,1,,,,,,,,,,,,,,,,
Ch. 1 Input voltage exceeded compliance limit.,3899837899.35725,200.000549316406,-45382.5703125,90,15.314,203.401,0,-0.03221917,,,0.4359754,2.293708,0.1,0,0.02033841,0.02033841,-1.143691E-05,,,,,,100,-65.47504,-70.91714,,,,,,,,,,,,,,,,,,,,,48536448,0,1,6,1,,,,,,,,,,,,,,,,
Ch. 1 Input voltage exceeded compliance limit.,3899837918.83316,200.000411987305,-46360.1328125,90,15.321,203.8143,0,-0.03141645,,,0.4359754,2.293708,0.1,0,0.02037974,0.02037973,-1.117463E-05,,,,,,100,-102.9692,-63.90808,,,,,,,,,,,,,,,,,,,,,48536448,0,1,6,1,,,,,,,,,,,,,,,,
Ch. 1 Input voltage exceeded compliance limit.,3899837939.94673,200.001129150391,-47422.5703125,90,15.33,204.03,0,-0.04965278,,,0.4359754,2.293708,0.1,0,0.02040132,0.02040131,-1.767987E-05,,,,,,100,-59.84743,-65.51394,,,,,,,,,,,,,,,,,,,,,48536448,0,1,6,1,,,,,,,,,,,,,,,,
Ch. 1 Input voltage exceeded compliance limit.,3899837964.75169,200.001342773438,-48665.66015625,90,15.322,203.9166,0,-0.04448964,,,0.4359754,2.293708,0.1,0,0.02038997,0.02038996,-1.583262E-05,,,,,,100,-83.13132,-68.47288,,,,,,,,,,,,,,,,,,,,,48536448,0,1,6,1,,,,,,,,,,,,,,,,
Ch. 1 Input voltage exceeded compliance limit.,3899837985.95498,200.001068115234,-49728.37890625,90,15.32,203.8541,0,-0.03578227,,,0.4359754,2.293708,0.1,0,0.02038372,0.02038372,-1.273001E-05,,,,,,100,-72.50525,-69.4961,,,,,,,,,,,,,,,,,,,,,48536448,0,1,6,1,,,,,,,,,,,,,,,,
Ch. 1 Input voltage exceeded compliance limit.,3899838005.06503,199.999557495117,-50686.5703125,90,15.341,204.2539,0,-0.02132202,,,0.4359754,2.293708,0.1,0,0.0204237,0.0204237,-7.600464E-06,,,,,,100,-62.67773,-73.10826,,,,,,,,,,,,,,,,,,,,,48536448,0,1,6,1,,,,,,,,,,,,,,,,
Ch. 1 Input voltage exceeded compliance limit.,3899838030.16313,200.001724243164,-51944.33984375,90,15.351,204.1828,0,-0.03509938,,,0.4359754,2.293708,0.1,0,0.02041658,0.02041658,-1.250719E-05,,,,,,100,-71.09039,-68.47224,,,,,,,,,,,,,,,,,,,,,48536448,0,1,6,1,,,,,,,,,,,,,,,,
Ch. 1 Input voltage exceeded compliance limit.,3899838051.25819,200.001342773438,-53002.2578125,90,15.358,204.0942,0,-0.05294809,,,0.4359754,2.293708,0.1,0,0.02040774,0.02040773,-1.885917E-05,,,,,,100,-71.45865,-62.6741,,,,,,,,,,,,,,,,,,,,,48536448,0,1,6,1,,,,,,,,,,,,,,,,
Ch. 1 Input voltage exceeded compliance limit.,3899838071.20094,199.999557495117,-54000.50390625,90,15.371,204.1822,0,-0.03254321,,,0.4359754,2.293708,0.1,0,0.02041653,0.02041652,-1.159631E-05,,,,,,100,-62.33299,-74.99262,,,,,,,,,,,,,,,,,,,,,48536448,0,1,6,1,,,,,,,,,,,,,,,,
Ch. 1 Input voltage exceeded compliance limit.,3899838092.0738,200.000869750977,-55048.13671875,90,15.371,204.2397,0,-0.01012272,,,0.4359754,2.293708,0.1,0,0.02042227,0.02042227,-3.608102E-06,,,,,,100,-64.23232,-60.32694,,,,,,,,,,,,,,,,,,,,,48536448,0,1,6,1,,,,,,,,,,,,,,,,
Ch. 1 Input voltage exceeded compliance limit.,3899838111.68859,200.000549316406,-56030.375,90,15.385,204.2522,0,-0.03430123,,,0.4359754,2.293708,0.1,0,0.02042353,0.02042352,-1.222694E-05,,,,,,100,-72.5006,-68.98332,,,,,,,,,,,,,,,,,,,,,48536448,0,1,6,1,,,,,,,,,,,,,,,,
Ch. 1 Input voltage exceeded compliance limit.,3899838132.78374,200.001266479492,-57088.078125,90,15.404,204.5169,0,-0.03854734,,,0.4359754,2.293708,0.1,0,0.02045,0.02044999,-1.375831E-05,,,,,,100,-61.80252,-75.85084,,,,,,,,,,,,,,,,,,,,,48536448,0,1,6,1,,,,,,,,,,,,,,,,
Ch. 1 Input voltage exceeded compliance limit.,3899838157.9573,199.999740600586,-58351.30859375,90,15.41,204.7314,0,-0.03406264,,,0.4359754,2.293708,0.1,0,0.02047145,0.02047144,-1.217038E-05,,,,,,100,-66.72177,-81.42925,,,,,,,,,,,,,,,,,,,,,48536448,0,1,6,1,,,,,,,,,,,,,,,,
Ch. 1 Input voltage exceeded compliance limit.,3899838177.73973,200.001266479492,-59343.453125,90,15.401,204.7482,0,-0.05064182,,,0.4359754,2.293708,0.1,0,0.02047313,0.02047312,-1.809551E-05,,,,,,100,-61.9125,-70.223,,,,,,,,,,,,,,,,,,,,,48536448,0,1,6,1,,,,,,,,,,,,,,,,
Ch. 1 Input voltage exceeded compliance limit.,3899838198.59123,200.000015258789,-60386.125,90,15.399,205.257,0,-0.04154222,,,0.4359754,2.293708,0.1,0,0.02052401,0.020524,-1.48809E-05,,,,,,100,-70.1278,-70.78131,,,,,,,,,,,,,,,,,,,,,48536448,0,1,6,1,,,,,,,,,,,,,,,,
Ch. 1 Input voltage exceeded compliance limit.,3899838218.29658,199.999420166016,-61373.6640625,90,15.408,205.2369,0,-0.04844414,,,0.4359754,2.293708,0.1,0,0.020522,0.02052199,-1.735155E-05,,,,,,100,-66.04725,-79.79332,,,,,,,,,,,,,,,,,,,,,48536448,0,1,6,1,,,,,,,,,,,,,,,,
Ch. 1 Input voltage exceeded compliance limit.,3899838239.51381,199.999877929688,-62441.10546875,90,15.418,205.6098,0,-0.02912481,,,0.4359754,2.293708,0.1,0,0.02055927,0.02055927,-1.045077E-05,,,,,,100,-65.10648,-92.15748,,,,,,,,,,,,,,,,,,,,,48536448,0,1,6,1,,,,,,,,,,,,,,,,
Ch. 1 Input voltage exceeded compliance limit.,3899838258.7983,200.000869750977,-63403.44140625,90,15.435,205.608,0,-0.0497919,,,0.4359754,2.293708,0.1,0,0.0205591,0.0205591,-1.786653E-05,,,,,,100,-80.94604,-68.20451,,,,,,,,,,,,,,,,,,,,,48536448,0,1,6,1,,,,,,,,,,,,,,,,
Ch. 1 Input voltage exceeded compliance limit.,3899838280.03597,200.000732421875,-64471.828125,90,15.452,205.7282,0,-0.02035166,,,0.4359754,2.293708,0.1,0,0.02057111,0.02057111,-7.306929E-06,,,,,,100,-65.58604,-63.18335,,,,,,,,,,,,,,,,,,,,,48536448,0,1,6,1,,,,,,,,,,,,,,,,
Ch. 1 Input voltage exceeded compliance limit.,3899838300.10955,199.999618530273,-65474.31640625,90,15.437,205.4775,0,-0.05359546,,,0.4359754,2.293708,0.1,0,0.02054606,0.02054605,-1.921913E-05,,,,,,100,-59.38315,-62.18807,,,,,,,,,,,,,,,,,,,,,48536448,0,1,6,1,,,,,,,,,,,,,,,,
Ch. 1 Input voltage exceeded compliance limit.,3899838321.27286,200.001129150391,-66536.6953125,90,15.454,205.5922,0,-0.01826678,,,0.4359754,2.293708,0.1,0,0.02055752,0.02055752,-6.554056E-06,,,,,,100,-78.91949,-75.99588,,,,,,,,,,,,,,,,,,,,,48536448,0,1,6,1,,,,,,,,,,,,,,,,
Ch. 1 Input voltage exceeded compliance limit.,3899838346.38602,200.001724243164,-67795.546875,90,15.465,205.9086,0,-0.03581922,,,0.4359754,2.293708,0.1,0,0.02058915,0.02058914,-1.287158E-05,,,,,,100,-67.78848,-64.5172,,,,,,,,,,,,,,,,,,,,,48536448,0,1,6,1,,,,,,,,,,,,,,,,
Ch. 1 Input voltage exceeded compliance limit.,3899838366.04406,200.000015258789,-68782.9140625,90,15.506,206.1312,0,-0.02943731,,,0.4359754,2.293708,0.1,0,0.02061141,0.02061141,-1.058969E-05,,,,,,100,-62.37131,-72.63258,,,,,,,,,,,,,,,,,,,,,48536448,0,1,6,1,,,,,,,,,,,,,,,,
Ch. 1 Input voltage exceeded compliance limit.,3899838387.07582,200.001342773438,-69835.6796875,90,15.502,205.9956,0,-0.03090032,,,0.4359754,2.293708,0.1,0,0.02059785,0.02059785,-1.110867E-05,,,,,,100,-61.26484,-69.43053,,,,,,,,,,,,,,,,,,,,,48536448,0,1,6,1,,,,,,,,,,,,,,,,
Ch. 1 Input voltage exceeded compliance limit.,3899838406.80598,200.001266479492,-70823.25,90,15.518,206.3129,0,-0.05005565,,,0.4359754,2.293708,0.1,0,0.02062958,0.02062958,-1.802274E-05,,,,,,100,-62.73042,-66.95011,,,,,,,,,,,,,,,,,,,,,48536448,0,1,6,1,,,,,,,,,,,,,,,,
Ch. 1 Input voltage exceeded compliance limit.,3899838428.19686,200.001129150391,-71900.5390625,90,15.519,206.4221,0,-0.03107385,,,0.4359754,2.293708,0.1,0,0.0206405,0.0206405,-1.119419E-05,,,,,,100,-60.90167,-61.41589,,,,,,,,,,,,,,,,,,,,,48536448,0,1,6,1,,,,,,,,,,,,,,,,
Ch. 1 Input voltage exceeded compliance limit.,3899838453.30132,200.001266479492,-73158.578125,90,15.557,206.8265,0,-0.0252477,,,0.4359754,2.293708,0.1,0,0.02068094,0.02068093,-9.11317E-06,,,,,,100,-65.07996,-77.05324,,,,,,,,,,,,,,,,,,,,,48536448,0,1,6,1,,,,,,,,,,,,,,,,
Ch. 1 Input voltage exceeded compliance limit.,3899838474.34332,199.999160766602,-74211.265625,90,15.571,206.9325,0,-0.01752723,,,0.4359754,2.293708,0.1,0,0.02069153,0.02069153,-6.329703E-06,,,,,,100,-60.9645,-81.31287,,,,,,,,,,,,,,,,,,,,,48536448,0,1,6,1,,,,,,,,,,,,,,,,
Ch. 1 Input voltage exceeded compliance limit.,3899838494.41064,200.000549316406,-75213.6171875,90,15.584,206.8495,0,-0.02509023,,,0.4359754,2.293708,0.1,0,0.02068323,0.02068323,-9.057332E-06,,,,,,100,-61.45666,-73.46458,,,,,,,,,,,,,,,,,,,,,48536448,0,1,6,1,,,,,,,,,,,,,,,,
Ch. 1 Input voltage exceeded compliance limit.,3899838514.17137,200.001129150391,-76206.09375,90,15.596,206.9679,0,-0.049453,,,0.4359754,2.293708,0.1,0,0.02069508,0.02069508,-1.786229E-05,,,,,,100,-66.8567,-71.59812,,,,,,,,,,,,,,,,,,,,,48536448,0,1,6,1,,,,,,,,,,,,,,,,
Ch. 1 Input voltage exceeded compliance limit.,3899838535.20765,200.000732421875,-77263.6171875,90,15.62,207.2619,0,-0.03930198,,,0.4359754,2.293708,0.1,0,0.02072447,0.02072447,-1.421593E-05,,,,,,100,-62.28894,-71.75027,,,,,,,,,,,,,,,,,,,,,48536448,0,1,6,1,,,,,,,,,,,,,,,,
Ch. 1 Input voltage exceeded compliance limit.,3899838560.18992,200.000076293945,-78512.2421875,90,15.637,207.4218,0,-0.01911243,,,0.4359754,2.293708,0.1,0,0.02074046,0.02074046,-6.918496E-06,,,,,,100,-72.90223,-69.13541,,,,,,,,,,,,,,,,,,,,,48536448,0,1,6,1,,,,,,,,,,,,,,,,
Ch. 1 Input voltage exceeded compliance limit.,3899838581.29748,199.999221801758,-79575.03125,90,15.637,207.6107,0,-0.0298609,,,0.4359754,2.293708,0.1,0,0.02075935,0.02075935,-1.081917E-05,,,,,,100,-68.75401,-73.631,,,,,,,,,,,,,,,,,,,,,48536448,0,1,6,1,,,,,,,,,,,,,,,,
Ch. 1 Input voltage exceeded compliance limit.,3899838601.30326,200.000549316406,-80572.34375,90,15.632,207.622,0,-0.02991432,,,0.4359754,2.293708,0.1,0,0.02076048,0.02076047,-1.083911E-05,,,,,,100,-72.85973,-71.36803,,,,,,,,,,,,,,,,,,,,,48536448,0,1,6,1,,,,,,,,,,,,,,,,
Ch. 1 Input voltage exceeded compliance limit.,3899838622.07165,200.000732421875,-81619.90625,90,15.626,208.0127,0,-0.03772462,,,0.4359754,2.293708,0.1,0,0.02079955,0.02079954,-1.369481E-05,,,,,,100,-62.81231,-71.19047,,,,,,,,,,,,,,,,,,,,,48536448,0,1,6,1,,,,,,,,,,,,,,,,
Ch. 1 Input voltage exceeded compliance limit.,3899838641.76442,199.999160766602,-82602.9609375,90,15.639,208.462,0,-0.02494537,,,0.4359754,2.293708,0.1,0,0.02084447,0.02084447,-9.075243E-06,,,,,,100,-75.57403,-74.1931,,,,,,,,,,,,,,,,,,,,,48536448,0,1,6,1,,,,,,,,,,,,,,,,
Ch. 1 Input voltage exceeded compliance limit.,3899838667.08975,199.999816894531,-83875.8125,90,15.635,208.6366,0,-0.01462089,,,0.4359754,2.293708,0.1,0,0.02086193,0.02086193,-5.323604E-06,,,,,,100,-84.39027,-66.75684,,,,,,,,,,,,,,,,,,,,,48536448,0,1,6,1,,,,,,,,,,,,,,,,
Ch. 1 Input voltage exceeded compliance limit.,3899838688.15173,200.000869750977,-84933.75,90,15.618,208.6765,0,-0.01819528,,,0.4359754,2.293708,0.1,0,0.02086592,0.02086591,-6.626338E-06,,,,,,100,-65.86837,-70.17373,,,,,,,,,,,,,,,,,,,,,48536448,0,1,6,1,,,,,,,,,,,,,,,,
Ch. 1 Input voltage exceeded compliance limit.,3899838707.95477,200.000274658203,-85926.0078125,90,15.61,208.7631,0,-0.03004054,,,0.4359754,2.293708,0.1,0,0.02087458,0.02087457,-1.094467E-05,,,,,,100,-76.53928,-72.38272,,,,,,,,,,,,,,,,,,,,,48536448,0,1,6,1,,,,,,,,,,,,,,,,
Ch. 1 Input voltage exceeded compliance limit.,3899838728.9057,200.000869750977,-86968.671875,90,15.603,209.0026,0,-0.02979285,,,0.4359754,2.293708,0.1,0,0.02089853,0.02089853,-1.086689E-05,,,,,,100,-67.75857,-67.98625,,,,,,,,,,,,,,,,,,,,,48536448,0,1,6,1,,,,,,,,,,,,,,,,
Ch. 1 Input voltage exceeded compliance limit.,3899838753.99504,200.000076293945,-88226.609375,90,15.592,208.8655,0,-0.02606197,,,0.4359754,2.293708,0.1,0,0.02088482,0.02088482,-9.499818E-06,,,,,,100,-62.80148,-71.68193,,,,,,,,,,,,,,,,,,,,,48536448,0,1,6,1,,,,,,,,,,,,,,,,
Ch. 1 Input voltage exceeded compliance limit.,3899838774.76697,200.001342773438,-89274.2578125,90,15.58,209.2232,0,-0.01757554,,,0.4359754,2.293708,0.1,0,0.02092059,0.02092059,-6.417412E-06,,,,,,100,-77.1748,-66.99269,,,,,,,,,,,,,,,,,,,,,48536448,0,1,6,1,,,,,,,,,,,,,,,,
Ch. 1 Input voltage exceeded compliance limit.,3899838794.70249,199.998947143555,-90000.203125,90,15.583,209.4279,0,-0.032022,,,0.4359754,2.293708,0.1,0,0.02094105,0.02094105,-1.170373E-05,,,,,,100,-65.41899,-69.61643,,,,,,,,,,,,,,,,,,,,,48536448,0,1,4,1,,,,,,,,,,,,,,,,
Ch. 1 Input voltage exceeded compliance limit.,3899838814.44127,200.000549316406,-90000.2265625,90,15.569,209.4173,0,-0.01260444,,,0.4359754,2.293708,0.1,0,0.02093999,0.02093999,-4.606569E-06,,,,,,100,-61.6475,-63.58786,,,,,,,,,,,,,,,,,,,,,48536448,0,1,4,1,,,,,,,,,,,,,,,,
Ch. 1 Input voltage exceeded compliance limit.,3899838819.48862,200.000274658203,-90000.2890625,90,15.573,209.3126,0,-0.04332015,,,0.4359754,2.293708,0.1,0,0.02092953,0.02092952,-1.582438E-05,,,,,,100,-66.23854,-75.36115,,,,,,,,,,,,,,,,,,,,,48536448,0,1,4,1,,,,,,,,,,,,,,,,